Workbook

Sheet Pivot Master1
B3: INVOICE | Q3: PROVISION
B4: BU | C4: TOTAL | Q4: BU | R4: TOTAL
B6: Invoice Net Amt (CLP) | I6: Customer | Q6: Provision Net Amt (CLP) | X6: Customer
B7: Year | C7: Invoice Received | D7: Impact Month | E7: Invoice Registered | F7: Invoice Status | G7: Commission Type | H7: Doc Type | I7: FALABELLA (DIRECT) | J7: PARIS (FULLKOM) | K7: WALMART (FULLKOM) | L7: RIPLEY (FULLKOM) | M7: MERCADO PAGO | N7: TRANSBANK | O7: OMS (V SOPTEC) | Q7: Year | R7: Invoice Received | S7: Impact Month | T7: Invoice Registered | U7: Invoice Status | V7: Commission Type | W7: Doc Type | X7: FALABELLA (DIRECT) | Y7: PARIS (FULLKOM) | Z7: WALMART (FULLKOM) | AA7: RIPLEY (FULLKOM) | AB7: MERCADO PAGO | AC7: TRANSBANK | AD7: OMS (V SOPTEC)
B8: 2026 | C8: MAY | D8: JUL (Provision) | E8: JUL | F8: AP Completed | G8: Commission (2da Quincena) | H8: Invoice | J8: 11257458 | K8: 7477508 | L8: 990593 | Q8: 2026 | R8: MAY | S8: JUL (Provision) | T8: JUL | U8: AP Completed | V8: Commission (2da Quincena) | W8: Invoice
B9: 2026 | C9: MAY | D9: JUL (Provision) | E9: AUG | F9: AP Completed | G9: Monthly Commission | H9: Invoice | N9: 4393086 | Q9: 2026 | R9: MAY | S9: JUL (Provision) | T9: AUG | U9: AP Completed | V9: Monthly Commission | W9: Invoice
B10: 2026 | C10: MAY | D10: JUL (Provision) | E10: Rejected | F10: Rejected | G10: Monthly Commission | H10: Invoice | M10: 5049775 | Q10: 2026 | R10: MAY | S10: JUL (Provision) | T10: Rejected | U10: Rejected | V10: Monthly Commission | W10: Invoice
B11: 2026 | C11: MAY Total | J11: 11257458 | K11: 7477508 | L11: 990593 | M11: 5049775 | N11: 4393086 | Q11: 2026 | R11: MAY Total
B12: 2026 | C12: JUN | D12: JUL (Provision) | E12: JUL | F12: AP Completed | G12: Commission (1era Quincena) | H12: Invoice | J12: 41580654 | K12: 29182345 | L12: 6642066 | Q12: 2026 | R12: JUN | S12: JUL (Provision) | T12: JUL | U12: AP Completed | V12: Commission (1era Quincena) | W12: Invoice | Y12: 31782550 | Z12: 27262067 | AA12: 5811311.5
B13: 2026 | C13: JUN | D13: JUL (Provision) | E13: JUL | F13: AP Completed | G13: Commission (2da Quincena) | H13: Invoice | J13: 13569540 | K13: 6754211 | L13: 2368348 | Q13: 2026 | R13: JUN | S13: JUL (Provision) | T13: JUL | U13: AP Completed | V13: Commission (2da Quincena) | W13: Invoice | Y13: 14193628 | Z13: 6861185.2 | AA13: 2960848
B14: 2026 | C14: JUN | D14: JUL (Provision) | E14: JUL | F14: AP Completed | G14: Commission (In transit) | H14: Invoice | K14: 0 | L14: 0 | Q14: 2026 | R14: JUN | S14: JUL (Provision) | T14: JUL | U14: AP Completed | V14: Commission (In transit) | W14: Invoice | Z14: 8213814.3 | AA14: 1752661.4
B15: 2026 | C15: JUN | D15: JUL (Provision) | E15: JUL | F15: AP Completed | G15: Logistic Cost | H15: Invoice | J15: 35307369 | Q15: 2026 | R15: JUN | S15: JUL (Provision) | T15: JUL | U15: AP Completed | V15: Logistic Cost | W15: Invoice
B16: 2026 | C16: JUN | D16: JUL (Provision) | E16: AUG | F16: AP Completed | G16: Monthly Commission | H16: Invoice | I16: 2.5181058e+08 | M16: 8819906 | N16: 8153422 | Q16: 2026 | R16: JUN | S16: JUL (Provision) | T16: AUG | U16: AP Completed | V16: Monthly Commission | W16: Invoice | AB16: 8963409.4 | AC16: 15914399
B17: 2026 | C17: JUN | D17: JUL (Provision) | E17: AUG | F17: AP Completed | G17: Monthly Commission | H17: Credit Note | I17: -99583029 | Q17: 2026 | R17: JUN | S17: JUL (Provision) | T17: AUG | U17: AP Completed | V17: Monthly Commission | W17: Credit Note
B18: 2026 | C18: JUN Total | I18: 1.5222755e+08 | J18: 90457563 | K18: 35936556 | L18: 9010414 | M18: 8819906 | N18: 8153422 | Q18: 2026 | R18: JUN Total | Y18: 45976178 | Z18: 42337067 | AA18: 10524821 | AB18: 8963409.4 | AC18: 15914399
B19: 2026 | C19: JUL | D19: JUL (Provision) | E19: AUG | F19: AP Completed | G19: Monthly Commission | H19: Invoice | I19: 141164774 | Q19: 2026 | R19: JUL | S19: JUL (Provision) | T19: AUG | U19: AP Completed | V19: Monthly Commission | W19: Invoice | X19: 141164774
B20: 2026 | C20: JUL | D20: JUL (Provision) | E20: AUG | F20: AP Completed | G20: Monthly Commission | H20: Credit Note | I20: -59216876 | Q20: 2026 | R20: JUL | S20: JUL (Provision) | T20: AUG | U20: AP Completed | V20: Monthly Commission | W20: Credit Note | X20: -59216876
B21: 2026 | C21: JUL | D21: JUL (Provision) | E21: Pending | F21: Pending | G21: Monthly Commission | H21: Invoice | M21: 5778926 | N21: 6122740.6 | Q21: 2026 | R21: JUL | S21: JUL (Provision) | T21: Pending | U21: Pending | V21: Monthly Commission | W21: Invoice
B22: 2026 | C22: JUL | D22: JUL (Provision) | E22: Pending | F22: Pending | G22: Commission (1era Quincena) | H22: Invoice | J22: 17265549 | K22: 9202504.1 | L22: 2735581.8 | Q22: 2026 | R22: JUL | S22: JUL (Provision) | T22: Pending | U22: Pending | V22: Commission (1era Quincena) | W22: Invoice
B23: 2026 | C23: JUL | D23: JUL (Provision) | E23: Pending | F23: Pending | G23: Commission (2da Quincena) | H23: Invoice | J23: 16791454 | K23: 9167913.9 | L23: 6558778.3 | Q23: 2026 | R23: JUL | S23: JUL (Provision) | T23: Pending | U23: Pending | V23: Commission (2da Quincena) | W23: Invoice
B24: 2026 | C24: JUL | D24: JUL (Provision) | E24: Pending | F24: Pending | G24: Logistic Cost | H24: Invoice | J24: 34222222 | Q24: 2026 | R24: JUL | S24: JUL (Provision) | T24: Pending | U24: Pending | V24: Logistic Cost | W24: Invoice
B25: 2026 | C25: JUL Total | I25: 81947898 | J25: 68279225 | K25: 18370418 | L25: 9294360.1 | M25: 5778926 | N25: 6122740.6 | Q25: 2026 | R25: JUL Total | X25: 81947898
B26: 2026 | C26: AUG | D26: AUG (Provision) | E26: Pending | F26: Pending | G26: Monthly Commission | H26: Invoice | I26: 2.0333005e+08 | M26: 7255543 | N26: 0 | O26: 2378590 | Q26: 2026 | R26: AUG | S26: AUG (Provision) | T26: Pending | U26: Pending | V26: Monthly Commission | W26: Invoice | AB26: 0 | AC26: 7261730.8 | AD26: 0
B27: 2026 | C27: AUG | D27: AUG (Provision) | E27: Pending | F27: Pending | G27: Monthly Commission | H27: Credit Note | I27: -82305000 | Q27: 2026 | R27: AUG | S27: AUG (Provision) | T27: Pending | U27: Pending | V27: Monthly Commission | W27: Credit Note
B28: 2026 | C28: AUG | D28: AUG (Provision) | E28: Pending | F28: Pending | G28: Commission (1era Quincena) | H28: Invoice | J28: 0 | K28: 0 | L28: 0 | Q28: 2026 | R28: AUG | S28: AUG (Provision) | T28: Pending | U28: Pending | V28: Commission (1era Quincena) | W28: Invoice | Y28: 11104183 | Z28: 10173825 | AA28: 7249876.2
B29: 2026 | C29: AUG | D29: AUG (Provision) | E29: Pending | F29: Pending | G29: Commission (2da Quincena) | H29: Invoice | J29: 0 | K29: 0 | L29: 0 | Q29: 2026 | R29: AUG | S29: AUG (Provision) | T29: Pending | U29: Pending | V29: Commission (2da Quincena) | W29: Invoice | Y29: 14355291 | Z29: 5460548.2 | AA29: 4291111
B30: 2026 | C30: AUG Total | I30: 1.2102505e+08 | J30: 0 | K30: 0 | L30: 0 | M30: 7255543 | N30: 0 | O30: 2378590 | Q30: 2026 | R30: AUG Total | Y30: 25459474 | Z30: 15634373 | AA30: 11540987 | AB30: 0 | AC30: 7261730.8 | AD30: 0
B31: Grand Total | I31: 3.552005e+08 | J31: 1.6999425e+08 | K31: 61784482 | L31: 19295367 | M31: 26904150 | N31: 18669249 | O31: 2378590 | Q31: Grand Total | X31: 81947898 | Y31: 71435651 | Z31: 57971440 | AA31: 22065808 | AB31: 8963409.4 | AC31: 23176130 | AD31: 0

Sheet Master 1_BU
D2: Incluir al final toda la info de Map2
B4: Year | C4: Cut Date | D4: Invoice Received | E4: Impact Month | F4: Invoice Registered | G4: Invoice Date | H4: Invoice Number | I4: Customer | J4: OBS/3P | K4: BU | L4: Division | M4: Invoice Net Amt (CLP) | N4: VAT (CLP) | O4: Total Amt (CLP) | P4: Invoice Net Amt (USD) | Q4: VAT (USD) | R4: Total Amt (USD) | S4: FX Rate | T4: Commission Type | U4: Provision | V4: Doc Type | W4: Variable /Fixed | X4: Invoice Status | Y4: BU | Z4: Provision Net Amt (CLP) | AA4: Provision VAT (CLP) | AB4: Provision Amt (CLP) | AC4: Provision Net Amt (USD) | AD4: Provision VAT (USD) | AE4: Provision Amt (USD) | AF4: Invoice URL
B5: 2026 | C5: Jun21 to Jul20 | D5: JUL | E5: JUL (Provision) | F5: AUG | G5: 46230 | H5: 478270 | I5: FALABELLA (DIRECT) | J5: =IFERROR(VLOOKUP(I5,Map!$F$18:$G$56,2,0),"Add in Map") -> 3P | K5: =VLOOKUP(L5,Map!$C$18:$D$29,2,0) -> CNT | L5: Refrigeration | M5: 24645503 | N5: =IF(L5="TOTAL",(M5*0.19),0) -> 0 | O5: =M5*1.19 -> 29328148 | P5: =M5/S5 -> 26672.622 | Q5: =IF(L5="TOTAL",(P5*0.19),0) -> 0 | R5: =P5*1.19 -> 31740.42 | S5: =INDEX(FX!$D$3:$O$19,MATCH(B5,FX!$B$3:$B$32,0),MATCH(D5,FX!$D$2:$O$2,0)) -> 924 | T5: Monthly Commission | U5: Provision (Based on External Report) | V5: Invoice | W5: =VLOOKUP(I5,Map!$F$18:$H$51,3,0) -> Variable | X5: AP Completed | Y5: =VLOOKUP(L5,Map!$C$18:$D$29,2,0) -> CNT | Z5: 24645503 | AA5: =IF(Y5="TOTAL",(Z5*0.19),0) -> 0 | AB5: =Z5*1.19 -> 29328148 | AC5: =Z5/S5 -> 26672.622 | AD5: =IF(Y5="TOTAL",(AC5*0.19),0) -> 0 | AE5: =AC5*1.19 -> 31740.42
B6: 2026 | C6: Jun21 to Jul20 | D6: JUL | E6: JUL (Provision) | F6: AUG | G6: 46230 | H6: 478270 | I6: FALABELLA (DIRECT) | J6: =IFERROR(VLOOKUP(I6,Map!$F$18:$G$56,2,0),"Add in Map") -> 3P | K6: =VLOOKUP(L6,Map!$C$18:$D$29,2,0) -> CVT | L6: Cooking | M6: 291662.76 | N6: =IF(L6="TOTAL",(M6*0.19),0) -> 0 | O6: =M6*1.19 -> 347078.68 | P6: =M6/S6 -> 315.65233 | Q6: =IF(L6="TOTAL",(P6*0.19),0) -> 0 | R6: =P6*1.19 -> 375.62628 | S6: =INDEX(FX!$D$3:$O$19,MATCH(B6,FX!$B$3:$B$32,0),MATCH(D6,FX!$D$2:$O$2,0)) -> 924 | T6: Monthly Commission | U6: Provision (Based on External Report) | V6: Invoice | W6: =VLOOKUP(I6,Map!$F$18:$H$51,3,0) -> Variable | X6: AP Completed | Y6: =VLOOKUP(L6,Map!$C$18:$D$29,2,0) -> CVT | Z6: 291662.76 | AA6: =IF(Y6="TOTAL",(Z6*0.19),0) -> 0 | AB6: =Z6*1.19 -> 347078.68 | AC6: =Z6/S6 -> 315.65233 | AD6: =IF(Y6="TOTAL",(AC6*0.19),0) -> 0 | AE6: =AC6*1.19 -> 375.62628
B7: 2026 | C7: Jun21 to Jul20 | D7: JUL | E7: JUL (Provision) | F7: AUG | G7: 46230 | H7: 478270 | I7: FALABELLA (DIRECT) | J7: =IFERROR(VLOOKUP(I7,Map!$F$18:$G$56,2,0),"Add in Map") -> 3P | K7: =VLOOKUP(L7,Map!$C$18:$D$29,2,0) -> CDT | L7: Dishwasher | M7: 1020819.6 | N7: =IF(L7="TOTAL",(M7*0.19),0) -> 0 | O7: =M7*1.19 -> 1214775.4 | P7: =M7/S7 -> 1104.7832 | Q7: =IF(L7="TOTAL",(P7*0.19),0) -> 0 | R7: =P7*1.19 -> 1314.692 | S7: =INDEX(FX!$D$3:$O$19,MATCH(B7,FX!$B$3:$B$32,0),MATCH(D7,FX!$D$2:$O$2,0)) -> 924 | T7: Monthly Commission | U7: Provision (Based on External Report) | V7: Invoice | W7: =VLOOKUP(I7,Map!$F$18:$H$51,3,0) -> Variable | X7: AP Completed | Y7: =VLOOKUP(L7,Map!$C$18:$D$29,2,0) -> CDT | Z7: 1020819.6 | AA7: =IF(Y7="TOTAL",(Z7*0.19),0) -> 0 | AB7: =Z7*1.19 -> 1214775.4 | AC7: =Z7/S7 -> 1104.7832 | AD7: =IF(Y7="TOTAL",(AC7*0.19),0) -> 0 | AE7: =AC7*1.19 -> 1314.692
B8: 2026 | C8: Jun21 to Jul20 | D8: JUL | E8: JUL (Provision) | F8: AUG | G8: 46230 | H8: 478270 | I8: FALABELLA (DIRECT) | J8: =IFERROR(VLOOKUP(I8,Map!$F$18:$G$56,2,0),"Add in Map") -> 3P | K8: =VLOOKUP(L8,Map!$C$18:$D$29,2,0) -> DFT | L8: WM | M8: 73207352 | N8: =IF(L8="TOTAL",(M8*0.19),0) -> 0 | O8: =M8*1.19 -> 87116749 | P8: =M8/S8 -> 79228.736 | Q8: =IF(L8="TOTAL",(P8*0.19),0) -> 0 | R8: =P8*1.19 -> 94282.196 | S8: =INDEX(FX!$D$3:$O$19,MATCH(B8,FX!$B$3:$B$32,0),MATCH(D8,FX!$D$2:$O$2,0)) -> 924 | T8: Monthly Commission | U8: Provision (Based on External Report) | V8: Invoice | W8: =VLOOKUP(I8,Map!$F$18:$H$51,3,0) -> Variable | X8: AP Completed | Y8: =VLOOKUP(L8,Map!$C$18:$D$29,2,0) -> DFT | Z8: 73207352 | AA8: =IF(Y8="TOTAL",(Z8*0.19),0) -> 0 | AB8: =Z8*1.19 -> 87116749 | AC8: =Z8/S8 -> 79228.736 | AD8: =IF(Y8="TOTAL",(AC8*0.19),0) -> 0 | AE8: =AC8*1.19 -> 94282.196
B9: 2026 | C9: Jun21 to Jul20 | D9: JUL | E9: JUL (Provision) | F9: AUG | G9: 46230 | H9: 478270 | I9: FALABELLA (DIRECT) | J9: =IFERROR(VLOOKUP(I9,Map!$F$18:$G$56,2,0),"Add in Map") -> 3P | K9: =VLOOKUP(L9,Map!$C$18:$D$29,2,0) -> DVT | L9: VCC | M9: 145831.38 | N9: =IF(L9="TOTAL",(M9*0.19),0) -> 0 | O9: =M9*1.19 -> 173539.34 | P9: =M9/S9 -> 157.82617 | Q9: =IF(L9="TOTAL",(P9*0.19),0) -> 0 | R9: =P9*1.19 -> 187.81314 | S9: =INDEX(FX!$D$3:$O$19,MATCH(B9,FX!$B$3:$B$32,0),MATCH(D9,FX!$D$2:$O$2,0)) -> 924 | T9: Monthly Commission | U9: Provision (Based on External Report) | V9: Invoice | W9: =VLOOKUP(I9,Map!$F$18:$H$51,3,0) -> Variable | X9: AP Completed | Y9: =VLOOKUP(L9,Map!$C$18:$D$29,2,0) -> DVT | Z9: 145831.38 | AA9: =IF(Y9="TOTAL",(Z9*0.19),0) -> 0 | AB9: =Z9*1.19 -> 173539.34 | AC9: =Z9/S9 -> 157.82617 | AD9: =IF(Y9="TOTAL",(AC9*0.19),0) -> 0 | AE9: =AC9*1.19 -> 187.81314
B10: 2026 | C10: Jun21 to Jul20 | D10: JUL | E10: JUL (Provision) | F10: AUG | G10: 46230 | H10: 478270 | I10: FALABELLA (DIRECT) | J10: =IFERROR(VLOOKUP(I10,Map!$F$18:$G$56,2,0),"Add in Map") -> 3P | K10: =VLOOKUP(L10,Map!$C$18:$D$29,2,0) -> GLT | L10: Television | M10: 34707868 | N10: =IF(L10="TOTAL",(M10*0.19),0) -> 0 | O10: =M10*1.19 -> 41302363 | P10: =M10/S10 -> 37562.628 | Q10: =IF(L10="TOTAL",(P10*0.19),0) -> 0 | R10: =P10*1.19 -> 44699.527 | S10: =INDEX(FX!$D$3:$O$19,MATCH(B10,FX!$B$3:$B$32,0),MATCH(D10,FX!$D$2:$O$2,0)) -> 924 | T10: Monthly Commission | U10: Provision (Based on External Report) | V10: Invoice | W10: =VLOOKUP(I10,Map!$F$18:$H$51,3,0) -> Variable | X10: AP Completed | Y10: =VLOOKUP(L10,Map!$C$18:$D$29,2,0) -> GLT | Z10: 34707868 | AA10: =IF(Y10="TOTAL",(Z10*0.19),0) -> 0 | AB10: =Z10*1.19 -> 41302363 | AC10: =Z10/S10 -> 37562.628 | AD10: =IF(Y10="TOTAL",(AC10*0.19),0) -> 0 | AE10: =AC10*1.19 -> 44699.527
B11: 2026 | C11: Jun21 to Jul20 | D11: JUL | E11: JUL (Provision) | F11: AUG | G11: 46230 | H11: 478270 | I11: FALABELLA (DIRECT) | J11: =IFERROR(VLOOKUP(I11,Map!$F$18:$G$56,2,0),"Add in Map") -> 3P | K11: =VLOOKUP(L11,Map!$C$18:$D$29,2,0) -> PNT | L11: Audio | M11: 2187470.7 | N11: =IF(L11="TOTAL",(M11*0.19),0) -> 0 | O11: =M11*1.19 -> 2603090.1 | P11: =M11/S11 -> 2367.3925 | Q11: =IF(L11="TOTAL",(P11*0.19),0) -> 0 | R11: =P11*1.19 -> 2817.1971 | S11: =INDEX(FX!$D$3:$O$19,MATCH(B11,FX!$B$3:$B$32,0),MATCH(D11,FX!$D$2:$O$2,0)) -> 924 | T11: Monthly Commission | U11: Provision (Based on External Report) | V11: Invoice | W11: =VLOOKUP(I11,Map!$F$18:$H$51,3,0) -> Variable | X11: AP Completed | Y11: =VLOOKUP(L11,Map!$C$18:$D$29,2,0) -> PNT | Z11: 2187470.7 | AA11: =IF(Y11="TOTAL",(Z11*0.19),0) -> 0 | AB11: =Z11*1.19 -> 2603090.1 | AC11: =Z11/S11 -> 2367.3925 | AD11: =IF(Y11="TOTAL",(AC11*0.19),0) -> 0 | AE11: =AC11*1.19 -> 2817.1971
B12: 2026 | C12: Jun21 to Jul20 | D12: JUL | E12: JUL (Provision) | F12: AUG | G12: 46230 | H12: 478270 | I12: FALABELLA (DIRECT) | J12: =IFERROR(VLOOKUP(I12,Map!$F$18:$G$56,2,0),"Add in Map") -> 3P | K12: =VLOOKUP(L12,Map!$C$18:$D$29,2,0) -> GTT | L12: Monitor | M12: 3645784.5 | N12: =IF(L12="TOTAL",(M12*0.19),0) -> 0 | O12: =M12*1.19 -> 4338483.5 | P12: =M12/S12 -> 3945.6542 | Q12: =IF(L12="TOTAL",(P12*0.19),0) -> 0 | R12: =P12*1.19 -> 4695.3285 | S12: =INDEX(FX!$D$3:$O$19,MATCH(B12,FX!$B$3:$B$32,0),MATCH(D12,FX!$D$2:$O$2,0)) -> 924 | T12: Monthly Commission | U12: Provision (Based on External Report) | V12: Invoice | W12: =VLOOKUP(I12,Map!$F$18:$H$51,3,0) -> Variable | X12: AP Completed | Y12: =VLOOKUP(L12,Map!$C$18:$D$29,2,0) -> GTT | Z12: 3645784.5 | AA12: =IF(Y12="TOTAL",(Z12*0.19),0) -> 0 | AB12: =Z12*1.19 -> 4338483.5 | AC12: =Z12/S12 -> 3945.6542 | AD12: =IF(Y12="TOTAL",(AC12*0.19),0) -> 0 | AE12: =AC12*1.19 -> 4695.3285
B13: 2026 | C13: Jun21 to Jul20 | D13: JUL | E13: JUL (Provision) | F13: AUG | G13: 46230 | H13: 478270 | I13: FALABELLA (DIRECT) | J13: =IFERROR(VLOOKUP(I13,Map!$F$18:$G$56,2,0),"Add in Map") -> 3P | K13: =VLOOKUP(L13,Map!$C$18:$D$29,2,0) -> DGT | L13: RAC | M13: 1020819.6 | N13: =IF(L13="TOTAL",(M13*0.19),0) -> 0 | O13: =M13*1.19 -> 1214775.4 | P13: =M13/S13 -> 1104.7832 | Q13: =IF(L13="TOTAL",(P13*0.19),0) -> 0 | R13: =P13*1.19 -> 1314.692 | S13: =INDEX(FX!$D$3:$O$19,MATCH(B13,FX!$B$3:$B$32,0),MATCH(D13,FX!$D$2:$O$2,0)) -> 924 | T13: Monthly Commission | U13: Provision (Based on External Report) | V13: Invoice | W13: =VLOOKUP(I13,Map!$F$18:$H$51,3,0) -> Variable | X13: AP Completed | Y13: =VLOOKUP(L13,Map!$C$18:$D$29,2,0) -> DGT | Z13: 1020819.6 | AA13: =IF(Y13="TOTAL",(Z13*0.19),0) -> 0 | AB13: =Z13*1.19 -> 1214775.4 | AC13: =Z13/S13 -> 1104.7832 | AD13: =IF(Y13="TOTAL",(AC13*0.19),0) -> 0 | AE13: =AC13*1.19 -> 1314.692
B14: 2026 | C14: Jun21 to Jul20 | D14: JUL | E14: JUL (Provision) | F14: AUG | G14: 46230 | H14: 478270 | I14: FALABELLA (DIRECT) | J14: =IFERROR(VLOOKUP(I14,Map!$F$18:$G$56,2,0),"Add in Map") -> 3P | K14: =VLOOKUP(L14,Map!$C$18:$D$29,2,0) -> DLT | L14: Air Cleaner | M14: 291662.76 | N14: =IF(L14="TOTAL",(M14*0.19),0) -> 0 | O14: =M14*1.19 -> 347078.68 | P14: =M14/S14 -> 315.65233 | Q14: =IF(L14="TOTAL",(P14*0.19),0) -> 0 | R14: =P14*1.19 -> 375.62628 | S14: =INDEX(FX!$D$3:$O$19,MATCH(B14,FX!$B$3:$B$32,0),MATCH(D14,FX!$D$2:$O$2,0)) -> 924 | T14: Monthly Commission | U14: Provision (Based on External Report) | V14: Invoice | W14: =VLOOKUP(I14,Map!$F$18:$H$51,3,0) -> Variable | X14: AP Completed | Y14: =VLOOKUP(L14,Map!$C$18:$D$29,2,0) -> DLT | Z14: 291662.76 | AA14: =IF(Y14="TOTAL",(Z14*0.19),0) -> 0 | AB14: =Z14*1.19 -> 347078.68 | AC14: =Z14/S14 -> 315.65233 | AD14: =IF(Y14="TOTAL",(AC14*0.19),0) -> 0 | AE14: =AC14*1.19 -> 375.62628
B15: 2026 | C15: Jun21 to Jul20 | D15: JUL | E15: JUL (Provision) | F15: AUG | G15: 46230 | H15: 478270 | I15: FALABELLA (DIRECT) | J15: =IFERROR(VLOOKUP(I15,Map!$F$18:$G$56,2,0),"Add in Map") -> 3P | K15: =VLOOKUP(L15,Map!$C$18:$D$29,2,0) -> DMT | L15: SAC | M15: 0 | N15: =IF(L15="TOTAL",(M15*0.19),0) -> 0 | O15: =M15*1.19 -> 0 | P15: 0 | Q15: =IF(L15="TOTAL",(P15*0.19),0) -> 0 | R15: =P15*1.19 -> 0 | S15: =INDEX(FX!$D$3:$O$19,MATCH(B15,FX!$B$3:$B$32,0),MATCH(D15,FX!$D$2:$O$2,0)) -> 924 | T15: Monthly Commission | U15: Provision (Based on External Report) | V15: Invoice | W15: =VLOOKUP(I15,Map!$F$18:$H$51,3,0) -> Variable | X15: AP Completed | Y15: =VLOOKUP(L15,Map!$C$18:$D$29,2,0) -> DMT | Z15: 0 | AA15: =IF(Y15="TOTAL",(Z15*0.19),0) -> 0 | AB15: =Z15*1.19 -> 0 | AC15: =Z15/S15 -> 0 | AD15: =IF(Y15="TOTAL",(AC15*0.19),0) -> 0 | AE15: =AC15*1.19 -> 0
B16: 2026 | C16: Jun21 to Jul20 | D16: JUL | E16: JUL (Provision) | F16: AUG | G16: 46230 | H16: 478270 | I16: FALABELLA (DIRECT) | J16: =IFERROR(VLOOKUP(I16,Map!$F$18:$G$56,2,0),"Add in Map") -> 3P | K16: =VLOOKUP(L16,Map!$C$18:$D$29,2,0) -> TOTAL | L16: TOTAL | M16: =SUM(M5:M15) -> 141164774 | N16: =IF(L16="TOTAL",(M16*0.19),0) -> 26821307 | O16: =M16*1.19 -> 1.6798608e+08 | P16: =M16/S16 -> 152775.73 | Q16: =IF(L16="TOTAL",(P16*0.19),0) -> 29027.389 | R16: =P16*1.19 -> 181803.12 | S16: =INDEX(FX!$D$3:$O$19,MATCH(B16,FX!$B$3:$B$32,0),MATCH(D16,FX!$D$2:$O$2,0)) -> 924 | T16: Monthly Commission | U16: Provision (Based on External Report) | V16: Invoice | W16: =VLOOKUP(I16,Map!$F$18:$H$51,3,0) -> Variable | X16: AP Completed | Y16: =VLOOKUP(L16,Map!$C$18:$D$29,2,0) -> TOTAL | Z16: =SUM(Z5:Z15) -> 141164774 | AA16: =IF(Y16="TOTAL",(Z16*0.19),0) -> 26821307 | AB16: =Z16*1.19 -> 1.6798608e+08 | AC16: =Z16/S16 -> 152775.73 | AD16: =IF(Y16="TOTAL",(AC16*0.19),0) -> 29027.389 | AE16: =AC16*1.19 -> 181803.12 | AF16: http://lg2607.acepta.com/v01/5E0A125A9F4EB54908C00523002399A4BD42D7F9
B17: 2026 | C17: Jun21 to Jul20 | D17: JUL | E17: JUL (Provision) | F17: AUG | G17: 46230 | H17: 456288 | I17: FALABELLA (DIRECT) | J17: =IFERROR(VLOOKUP(I17,Map!$F$18:$G$56,2,0),"Add in Map") -> 3P | K17: =VLOOKUP(L17,Map!$C$18:$D$29,2,0) -> CNT | L17: Refrigeration | M17: -10338484 | N17: =IF(L17="TOTAL",(M17*0.19),0) -> 0 | O17: =M17*1.19 -> -12302795 | P17: =M17/S17 -> -11188.835 | Q17: =IF(L17="TOTAL",(P17*0.19),0) -> 0 | R17: =P17*1.19 -> -13314.714 | S17: =INDEX(FX!$D$3:$O$19,MATCH(B17,FX!$B$3:$B$32,0),MATCH(D17,FX!$D$2:$O$2,0)) -> 924 | T17: Monthly Commission | U17: Provision (Based on External Report) | V17: Credit Note | W17: =VLOOKUP(I17,Map!$F$18:$H$51,3,0) -> Variable | X17: AP Completed | Y17: =VLOOKUP(L17,Map!$C$18:$D$29,2,0) -> CNT | Z17: -10338484 | AA17: =IF(Y17="TOTAL",(Z17*0.19),0) -> 0 | AB17: =Z17*1.19 -> -12302795 | AC17: =Z17/S17 -> -11188.835 | AD17: =IF(Y17="TOTAL",(AC17*0.19),0) -> 0 | AE17: =AC17*1.19 -> -13314.714
B18: 2026 | C18: Jun21 to Jul20 | D18: JUL | E18: JUL (Provision) | F18: AUG | G18: 46230 | H18: 456288 | I18: FALABELLA (DIRECT) | J18: =IFERROR(VLOOKUP(I18,Map!$F$18:$G$56,2,0),"Add in Map") -> 3P | K18: =VLOOKUP(L18,Map!$C$18:$D$29,2,0) -> CVT | L18: Cooking | M18: -122348.92 | N18: =IF(L18="TOTAL",(M18*0.19),0) -> 0 | O18: =M18*1.19 -> -145595.21 | P18: =M18/S18 -> -132.41225 | Q18: =IF(L18="TOTAL",(P18*0.19),0) -> 0 | R18: =P18*1.19 -> -157.57058 | S18: =INDEX(FX!$D$3:$O$19,MATCH(B18,FX!$B$3:$B$32,0),MATCH(D18,FX!$D$2:$O$2,0)) -> 924 | T18: Monthly Commission | U18: Provision (Based on External Report) | V18: Credit Note | W18: =VLOOKUP(I18,Map!$F$18:$H$51,3,0) -> Variable | X18: AP Completed | Y18: =VLOOKUP(L18,Map!$C$18:$D$29,2,0) -> CVT | Z18: -122348.92 | AA18: =IF(Y18="TOTAL",(Z18*0.19),0) -> 0 | AB18: =Z18*1.19 -> -145595.21 | AC18: =Z18/S18 -> -132.41225 | AD18: =IF(Y18="TOTAL",(AC18*0.19),0) -> 0 | AE18: =AC18*1.19 -> -157.57058
B19: 2026 | C19: Jun21 to Jul20 | D19: JUL | E19: JUL (Provision) | F19: AUG | G19: 46230 | H19: 456288 | I19: FALABELLA (DIRECT) | J19: =IFERROR(VLOOKUP(I19,Map!$F$18:$G$56,2,0),"Add in Map") -> 3P | K19: =VLOOKUP(L19,Map!$C$18:$D$29,2,0) -> CDT | L19: Dishwasher | M19: -428221.21 | N19: =IF(L19="TOTAL",(M19*0.19),0) -> 0 | O19: =M19*1.19 -> -509583.24 | P19: =M19/S19 -> -463.44287 | Q19: =IF(L19="TOTAL",(P19*0.19),0) -> 0 | R19: =P19*1.19 -> -551.49701 | S19: =INDEX(FX!$D$3:$O$19,MATCH(B19,FX!$B$3:$B$32,0),MATCH(D19,FX!$D$2:$O$2,0)) -> 924 | T19: Monthly Commission | U19: Provision (Based on External Report) | V19: Credit Note | W19: =VLOOKUP(I19,Map!$F$18:$H$51,3,0) -> Variable | X19: AP Completed | Y19: =VLOOKUP(L19,Map!$C$18:$D$29,2,0) -> CDT | Z19: -428221.21 | AA19: =IF(Y19="TOTAL",(Z19*0.19),0) -> 0 | AB19: =Z19*1.19 -> -509583.24 | AC19: =Z19/S19 -> -463.44287 | AD19: =IF(Y19="TOTAL",(AC19*0.19),0) -> 0 | AE19: =AC19*1.19 -> -551.49701
B20: 2026 | C20: Jun21 to Jul20 | D20: JUL | E20: JUL (Provision) | F20: AUG | G20: 46230 | H20: 456288 | I20: FALABELLA (DIRECT) | J20: =IFERROR(VLOOKUP(I20,Map!$F$18:$G$56,2,0),"Add in Map") -> 3P | K20: =VLOOKUP(L20,Map!$C$18:$D$29,2,0) -> DFT | L20: WM | M20: -30709578 | N20: =IF(L20="TOTAL",(M20*0.19),0) -> 0 | O20: =M20*1.19 -> -36544398 | P20: =M20/S20 -> -33235.474 | Q20: =IF(L20="TOTAL",(P20*0.19),0) -> 0 | R20: =P20*1.19 -> -39550.214 | S20: =INDEX(FX!$D$3:$O$19,MATCH(B20,FX!$B$3:$B$32,0),MATCH(D20,FX!$D$2:$O$2,0)) -> 924 | T20: Monthly Commission | U20: Provision (Based on External Report) | V20: Credit Note | W20: =VLOOKUP(I20,Map!$F$18:$H$51,3,0) -> Variable | X20: AP Completed | Y20: =VLOOKUP(L20,Map!$C$18:$D$29,2,0) -> DFT | Z20: -30709578 | AA20: =IF(Y20="TOTAL",(Z20*0.19),0) -> 0 | AB20: =Z20*1.19 -> -36544398 | AC20: =Z20/S20 -> -33235.474 | AD20: =IF(Y20="TOTAL",(AC20*0.19),0) -> 0 | AE20: =AC20*1.19 -> -39550.214
B21: 2026 | C21: Jun21 to Jul20 | D21: JUL | E21: JUL (Provision) | F21: AUG | G21: 46230 | H21: 456288 | I21: FALABELLA (DIRECT) | J21: =IFERROR(VLOOKUP(I21,Map!$F$18:$G$56,2,0),"Add in Map") -> 3P | K21: =VLOOKUP(L21,Map!$C$18:$D$29,2,0) -> DVT | L21: VCC | M21: -61174.459 | N21: =IF(L21="TOTAL",(M21*0.19),0) -> 0 | O21: =M21*1.19 -> -72797.606 | P21: =M21/S21 -> -66.206124 | Q21: =IF(L21="TOTAL",(P21*0.19),0) -> 0 | R21: =P21*1.19 -> -78.785288 | S21: =INDEX(FX!$D$3:$O$19,MATCH(B21,FX!$B$3:$B$32,0),MATCH(D21,FX!$D$2:$O$2,0)) -> 924 | T21: Monthly Commission | U21: Provision (Based on External Report) | V21: Credit Note | W21: =VLOOKUP(I21,Map!$F$18:$H$51,3,0) -> Variable | X21: AP Completed | Y21: =VLOOKUP(L21,Map!$C$18:$D$29,2,0) -> DVT | Z21: -61174.459 | AA21: =IF(Y21="TOTAL",(Z21*0.19),0) -> 0 | AB21: =Z21*1.19 -> -72797.606 | AC21: =Z21/S21 -> -66.206124 | AD21: =IF(Y21="TOTAL",(AC21*0.19),0) -> 0 | AE21: =AC21*1.19 -> -78.785288
B22: 2026 | C22: Jun21 to Jul20 | D22: JUL | E22: JUL (Provision) | F22: AUG | G22: 46230 | H22: 456288 | I22: FALABELLA (DIRECT) | J22: =IFERROR(VLOOKUP(I22,Map!$F$18:$G$56,2,0),"Add in Map") -> 3P | K22: =VLOOKUP(L22,Map!$C$18:$D$29,2,0) -> GLT | L22: Television | M22: -14559521 | N22: =IF(L22="TOTAL",(M22*0.19),0) -> 0 | O22: =M22*1.19 -> -17325830 | P22: =M22/S22 -> -15757.058 | Q22: =IF(L22="TOTAL",(P22*0.19),0) -> 0 | R22: =P22*1.19 -> -18750.898 | S22: =INDEX(FX!$D$3:$O$19,MATCH(B22,FX!$B$3:$B$32,0),MATCH(D22,FX!$D$2:$O$2,0)) -> 924 | T22: Monthly Commission | U22: Provision (Based on External Report) | V22: Credit Note | W22: =VLOOKUP(I22,Map!$F$18:$H$51,3,0) -> Variable | X22: AP Completed | Y22: =VLOOKUP(L22,Map!$C$18:$D$29,2,0) -> GLT | Z22: -14559521 | AA22: =IF(Y22="TOTAL",(Z22*0.19),0) -> 0 | AB22: =Z22*1.19 -> -17325830 | AC22: =Z22/S22 -> -15757.058 | AD22: =IF(Y22="TOTAL",(AC22*0.19),0) -> 0 | AE22: =AC22*1.19 -> -18750.898
B23: 2026 | C23: Jun21 to Jul20 | D23: JUL | E23: JUL (Provision) | F23: AUG | G23: 46230 | H23: 456288 | I23: FALABELLA (DIRECT) | J23: =IFERROR(VLOOKUP(I23,Map!$F$18:$G$56,2,0),"Add in Map") -> 3P | K23: =VLOOKUP(L23,Map!$C$18:$D$29,2,0) -> PNT | L23: Audio | M23: -917616.88 | N23: =IF(L23="TOTAL",(M23*0.19),0) -> 0 | O23: =M23*1.19 -> -1091964.1 | P23: =M23/S23 -> -993.09186 | Q23: =IF(L23="TOTAL",(P23*0.19),0) -> 0 | R23: =P23*1.19 -> -1181.7793 | S23: =INDEX(FX!$D$3:$O$19,MATCH(B23,FX!$B$3:$B$32,0),MATCH(D23,FX!$D$2:$O$2,0)) -> 924 | T23: Monthly Commission | U23: Provision (Based on External Report) | V23: Credit Note | W23: =VLOOKUP(I23,Map!$F$18:$H$51,3,0) -> Variable | X23: AP Completed | Y23: =VLOOKUP(L23,Map!$C$18:$D$29,2,0) -> PNT | Z23: -917616.88 | AA23: =IF(Y23="TOTAL",(Z23*0.19),0) -> 0 | AB23: =Z23*1.19 -> -1091964.1 | AC23: =Z23/S23 -> -993.09186 | AD23: =IF(Y23="TOTAL",(AC23*0.19),0) -> 0 | AE23: =AC23*1.19 -> -1181.7793
B24: 2026 | C24: Jun21 to Jul20 | D24: JUL | E24: JUL (Provision) | F24: AUG | G24: 46230 | H24: 456288 | I24: FALABELLA (DIRECT) | J24: =IFERROR(VLOOKUP(I24,Map!$F$18:$G$56,2,0),"Add in Map") -> 3P | K24: =VLOOKUP(L24,Map!$C$18:$D$29,2,0) -> GTT | L24: Monitor | M24: -1529361.5 | N24: =IF(L24="TOTAL",(M24*0.19),0) -> 0 | O24: =M24*1.19 -> -1819940.1 | P24: =M24/S24 -> -1655.1531 | Q24: =IF(L24="TOTAL",(P24*0.19),0) -> 0 | R24: =P24*1.19 -> -1969.6322 | S24: =INDEX(FX!$D$3:$O$19,MATCH(B24,FX!$B$3:$B$32,0),MATCH(D24,FX!$D$2:$O$2,0)) -> 924 | T24: Monthly Commission | U24: Provision (Based on External Report) | V24: Credit Note | W24: =VLOOKUP(I24,Map!$F$18:$H$51,3,0) -> Variable | X24: AP Completed | Y24: =VLOOKUP(L24,Map!$C$18:$D$29,2,0) -> GTT | Z24: -1529361.5 | AA24: =IF(Y24="TOTAL",(Z24*0.19),0) -> 0 | AB24: =Z24*1.19 -> -1819940.1 | AC24: =Z24/S24 -> -1655.1531 | AD24: =IF(Y24="TOTAL",(AC24*0.19),0) -> 0 | AE24: =AC24*1.19 -> -1969.6322
B25: 2026 | C25: Jun21 to Jul20 | D25: JUL | E25: JUL (Provision) | F25: AUG | G25: 46230 | H25: 456288 | I25: FALABELLA (DIRECT) | J25: =IFERROR(VLOOKUP(I25,Map!$F$18:$G$56,2,0),"Add in Map") -> 3P | K25: =VLOOKUP(L25,Map!$C$18:$D$29,2,0) -> DGT | L25: RAC | M25: -428221.21 | N25: =IF(L25="TOTAL",(M25*0.19),0) -> 0 | O25: =M25*1.19 -> -509583.24 | P25: =M25/S25 -> -463.44287 | Q25: =IF(L25="TOTAL",(P25*0.19),0) -> 0 | R25: =P25*1.19 -> -551.49701 | S25: =INDEX(FX!$D$3:$O$19,MATCH(B25,FX!$B$3:$B$32,0),MATCH(D25,FX!$D$2:$O$2,0)) -> 924 | T25: Monthly Commission | U25: Provision (Based on External Report) | V25: Credit Note | W25: =VLOOKUP(I25,Map!$F$18:$H$51,3,0) -> Variable | X25: AP Completed | Y25: =VLOOKUP(L25,Map!$C$18:$D$29,2,0) -> DGT | Z25: -428221.21 | AA25: =IF(Y25="TOTAL",(Z25*0.19),0) -> 0 | AB25: =Z25*1.19 -> -509583.24 | AC25: =Z25/S25 -> -463.44287 | AD25: =IF(Y25="TOTAL",(AC25*0.19),0) -> 0 | AE25: =AC25*1.19 -> -551.49701
B26: 2026 | C26: Jun21 to Jul20 | D26: JUL | E26: JUL (Provision) | F26: AUG | G26: 46230 | H26: 456288 | I26: FALABELLA (DIRECT) | J26: =IFERROR(VLOOKUP(I26,Map!$F$18:$G$56,2,0),"Add in Map") -> 3P | K26: =VLOOKUP(L26,Map!$C$18:$D$29,2,0) -> DLT | L26: Air Cleaner | M26: -122348.92 | N26: =IF(L26="TOTAL",(M26*0.19),0) -> 0 | O26: =M26*1.19 -> -145595.21 | P26: =M26/S26 -> -132.41225 | Q26: =IF(L26="TOTAL",(P26*0.19),0) -> 0 | R26: =P26*1.19 -> -157.57058 | S26: =INDEX(FX!$D$3:$O$19,MATCH(B26,FX!$B$3:$B$32,0),MATCH(D26,FX!$D$2:$O$2,0)) -> 924 | T26: Monthly Commission | U26: Provision (Based on External Report) | V26: Credit Note | W26: =VLOOKUP(I26,Map!$F$18:$H$51,3,0) -> Variable | X26: AP Completed | Y26: =VLOOKUP(L26,Map!$C$18:$D$29,2,0) -> DLT | Z26: -122348.92 | AA26: =IF(Y26="TOTAL",(Z26*0.19),0) -> 0 | AB26: =Z26*1.19 -> -145595.21 | AC26: =Z26/S26 -> -132.41225 | AD26: =IF(Y26="TOTAL",(AC26*0.19),0) -> 0 | AE26: =AC26*1.19 -> -157.57058
B27: 2026 | C27: Jun21 to Jul20 | D27: JUL | E27: JUL (Provision) | F27: AUG | G27: 46230 | H27: 456288 | I27: FALABELLA (DIRECT) | J27: =IFERROR(VLOOKUP(I27,Map!$F$18:$G$56,2,0),"Add in Map") -> 3P | K27: =VLOOKUP(L27,Map!$C$18:$D$29,2,0) -> DMT | L27: SAC | M27: 0 | N27: =IF(L27="TOTAL",(M27*0.19),0) -> 0 | O27: =M27*1.19 -> 0 | P27: =M27/S27 -> 0 | Q27: =IF(L27="TOTAL",(P27*0.19),0) -> 0 | R27: =P27*1.19 -> 0 | S27: =INDEX(FX!$D$3:$O$19,MATCH(B27,FX!$B$3:$B$32,0),MATCH(D27,FX!$D$2:$O$2,0)) -> 924 | T27: Monthly Commission | U27: Provision (Based on External Report) | V27: Credit Note | W27: =VLOOKUP(I27,Map!$F$18:$H$51,3,0) -> Variable | X27: AP Completed | Y27: =VLOOKUP(L27,Map!$C$18:$D$29,2,0) -> DMT | Z27: 0 | AA27: =IF(Y27="TOTAL",(Z27*0.19),0) -> 0 | AB27: =Z27*1.19 -> 0 | AC27: =Z27/S27 -> 0 | AD27: =IF(Y27="TOTAL",(AC27*0.19),0) -> 0 | AE27: =AC27*1.19 -> 0
B28: 2026 | C28: Jun21 to Jul20 | D28: JUL | E28: JUL (Provision) | F28: AUG | G28: 46230 | H28: 456288 | I28: FALABELLA (DIRECT) | J28: =IFERROR(VLOOKUP(I28,Map!$F$18:$G$56,2,0),"Add in Map") -> 3P | K28: =VLOOKUP(L28,Map!$C$18:$D$29,2,0) -> TOTAL | L28: TOTAL | M28: =SUM(M17:M27) -> -59216876 | N28: =IF(L28="TOTAL",(M28*0.19),0) -> -11251206 | O28: =M28*1.19 -> -70468082 | P28: =M28/S28 -> -64087.528 | Q28: =IF(L28="TOTAL",(P28*0.19),0) -> -12176.63 | R28: =P28*1.19 -> -76264.158 | S28: =INDEX(FX!$D$3:$O$19,MATCH(B28,FX!$B$3:$B$32,0),MATCH(D28,FX!$D$2:$O$2,0)) -> 924 | T28: Monthly Commission | U28: Provision (Based on External Report) | V28: Credit Note | W28: =VLOOKUP(I28,Map!$F$18:$H$51,3,0) -> Variable | X28: AP Completed | Y28: =VLOOKUP(L28,Map!$C$18:$D$29,2,0) -> TOTAL | Z28: =SUM(Z17:Z27) -> -59216876 | AA28: =IF(Y28="TOTAL",(Z28*0.19),0) -> -11251206 | AB28: =Z28*1.19 -> -70468082 | AC28: =Z28/S28 -> -64087.528 | AD28: =IF(Y28="TOTAL",(AC28*0.19),0) -> -12176.63 | AE28: =AC28*1.19 -> -76264.158 | AF28: http://lg2607.acepta.com/v01/AD2F1E54CFEE4EA8AEAAF32C8EE536D5DD0B56A6
B29: 2026 | C29: Jun27 to Jul15 | D29: JUL | E29: JUL (Provision) | F29: Pending | I29: PARIS (FULLKOM) | J29: =IFERROR(VLOOKUP(I29,Map!$F$18:$G$56,2,0),"Add in Map") -> 3P | K29: =VLOOKUP(L29,Map!$C$18:$D$29,2,0) -> CNT | L29: Refrigeration | M29: 4169389.7 | N29: =IF(L29="TOTAL",(M29*0.19),0) -> 0 | O29: =M29*1.19 -> 4961573.7 | P29: =M29/S29 -> 4512.3265 | Q29: =IF(L29="TOTAL",(P29*0.19),0) -> 0 | R29: =P29*1.19 -> 5369.6685 | S29: =INDEX(FX!$D$3:$O$19,MATCH(B29,FX!$B$3:$B$32,0),MATCH(D29,FX!$D$2:$O$2,0)) -> 924 | T29: Commission (1era Quincena) | U29: Provision (Based on PO, One View) | V29: Invoice | W29: =VLOOKUP(I29,Map!$F$18:$H$51,3,0) -> Variable | X29: Pending | Y29: =VLOOKUP(L29,Map!$C$18:$D$29,2,0) -> CNT | AA29: =IF(Y29="TOTAL",(Z29*0.19),0) -> 0 | AB29: =Z29*1.19 -> 0 | AC29: =Z29/S29 -> 0 | AD29: =IF(Y29="TOTAL",(AC29*0.19),0) -> 0 | AE29: =AC29*1.19 -> 0
B30: 2026 | C30: Jun27 to Jul15 | D30: JUL | E30: JUL (Provision) | F30: Pending | I30: PARIS (FULLKOM) | J30: =IFERROR(VLOOKUP(I30,Map!$F$18:$G$56,2,0),"Add in Map") -> 3P | K30: =VLOOKUP(L30,Map!$C$18:$D$29,2,0) -> CVT | L30: Cooking | M30: 0 | N30: =IF(L30="TOTAL",(M30*0.19),0) -> 0 | O30: =M30*1.19 -> 0 | P30: =M30/S30 -> 0 | Q30: =IF(L30="TOTAL",(P30*0.19),0) -> 0 | R30: =P30*1.19 -> 0 | S30: =INDEX(FX!$D$3:$O$19,MATCH(B30,FX!$B$3:$B$32,0),MATCH(D30,FX!$D$2:$O$2,0)) -> 924 | T30: Commission (1era Quincena) | U30: Provision (Based on PO, One View) | V30: Invoice | W30: =VLOOKUP(I30,Map!$F$18:$H$51,3,0) -> Variable | X30: Pending | Y30: =VLOOKUP(L30,Map!$C$18:$D$29,2,0) -> CVT | AA30: =IF(Y30="TOTAL",(Z30*0.19),0) -> 0 | AB30: =Z30*1.19 -> 0 | AC30: =Z30/S30 -> 0 | AD30: =IF(Y30="TOTAL",(AC30*0.19),0) -> 0 | AE30: =AC30*1.19 -> 0
B31: 2026 | C31: Jun27 to Jul15 | D31: JUL | E31: JUL (Provision) | F31: Pending | I31: PARIS (FULLKOM) | J31: =IFERROR(VLOOKUP(I31,Map!$F$18:$G$56,2,0),"Add in Map") -> 3P | K31: =VLOOKUP(L31,Map!$C$18:$D$29,2,0) -> CDT | L31: Dishwasher | M31: 53453.713 | N31: =IF(L31="TOTAL",(M31*0.19),0) -> 0 | O31: =M31*1.19 -> 63609.919 | P31: =M31/S31 -> 57.850339 | Q31: =IF(L31="TOTAL",(P31*0.19),0) -> 0 | R31: =P31*1.19 -> 68.841904 | S31: =INDEX(FX!$D$3:$O$19,MATCH(B31,FX!$B$3:$B$32,0),MATCH(D31,FX!$D$2:$O$2,0)) -> 924 | T31: Commission (1era Quincena) | U31: Provision (Based on PO, One View) | V31: Invoice | W31: =VLOOKUP(I31,Map!$F$18:$H$51,3,0) -> Variable | X31: Pending | Y31: =VLOOKUP(L31,Map!$C$18:$D$29,2,0) -> CDT | AA31: =IF(Y31="TOTAL",(Z31*0.19),0) -> 0 | AB31: =Z31*1.19 -> 0 | AC31: =Z31/S31 -> 0 | AD31: =IF(Y31="TOTAL",(AC31*0.19),0) -> 0 | AE31: =AC31*1.19 -> 0
B32: 2026 | C32: Jun27 to Jul15 | D32: JUL | E32: JUL (Provision) | F32: Pending | I32: PARIS (FULLKOM) | J32: =IFERROR(VLOOKUP(I32,Map!$F$18:$G$56,2,0),"Add in Map") -> 3P | K32: =VLOOKUP(L32,Map!$C$18:$D$29,2,0) -> DFT | L32: WM | M32: 10049298 | N32: =IF(L32="TOTAL",(M32*0.19),0) -> 0 | O32: =M32*1.19 -> 11958665 | P32: =M32/S32 -> 10875.864 | Q32: =IF(L32="TOTAL",(P32*0.19),0) -> 0 | R32: =P32*1.19 -> 12942.278 | S32: =INDEX(FX!$D$3:$O$19,MATCH(B32,FX!$B$3:$B$32,0),MATCH(D32,FX!$D$2:$O$2,0)) -> 924 | T32: Commission (1era Quincena) | U32: Provision (Based on PO, One View) | V32: Invoice | W32: =VLOOKUP(I32,Map!$F$18:$H$51,3,0) -> Variable | X32: Pending | Y32: =VLOOKUP(L32,Map!$C$18:$D$29,2,0) -> DFT | AA32: =IF(Y32="TOTAL",(Z32*0.19),0) -> 0 | AB32: =Z32*1.19 -> 0 | AC32: =Z32/S32 -> 0 | AD32: =IF(Y32="TOTAL",(AC32*0.19),0) -> 0 | AE32: =AC32*1.19 -> 0
B33: 2026 | C33: Jun27 to Jul15 | D33: JUL | E33: JUL (Provision) | F33: Pending | I33: PARIS (FULLKOM) | J33: =IFERROR(VLOOKUP(I33,Map!$F$18:$G$56,2,0),"Add in Map") -> 3P | K33: =VLOOKUP(L33,Map!$C$18:$D$29,2,0) -> DVT | L33: VCC | M33: 0 | N33: =IF(L33="TOTAL",(M33*0.19),0) -> 0 | O33: =M33*1.19 -> 0 | P33: =M33/S33 -> 0 | Q33: =IF(L33="TOTAL",(P33*0.19),0) -> 0 | R33: =P33*1.19 -> 0 | S33: =INDEX(FX!$D$3:$O$19,MATCH(B33,FX!$B$3:$B$32,0),MATCH(D33,FX!$D$2:$O$2,0)) -> 924 | T33: Commission (1era Quincena) | U33: Provision (Based on PO, One View) | V33: Invoice | W33: =VLOOKUP(I33,Map!$F$18:$H$51,3,0) -> Variable | X33: Pending | Y33: =VLOOKUP(L33,Map!$C$18:$D$29,2,0) -> DVT | AA33: =IF(Y33="TOTAL",(Z33*0.19),0) -> 0 | AB33: =Z33*1.19 -> 0 | AC33: =Z33/S33 -> 0 | AD33: =IF(Y33="TOTAL",(AC33*0.19),0) -> 0 | AE33: =AC33*1.19 -> 0
B34: 2026 | C34: Jun27 to Jul15 | D34: JUL | E34: JUL (Provision) | F34: Pending | I34: PARIS (FULLKOM) | J34: =IFERROR(VLOOKUP(I34,Map!$F$18:$G$56,2,0),"Add in Map") -> 3P | K34: =VLOOKUP(L34,Map!$C$18:$D$29,2,0) -> GLT | L34: Television | M34: 2191602.3 | N34: =IF(L34="TOTAL",(M34*0.19),0) -> 0 | O34: =M34*1.19 -> 2608006.7 | P34: =M34/S34 -> 2371.8639 | Q34: =IF(L34="TOTAL",(P34*0.19),0) -> 0 | R34: =P34*1.19 -> 2822.5181 | S34: =INDEX(FX!$D$3:$O$19,MATCH(B34,FX!$B$3:$B$32,0),MATCH(D34,FX!$D$2:$O$2,0)) -> 924 | T34: Commission (1era Quincena) | U34: Provision (Based on PO, One View) | V34: Invoice | W34: =VLOOKUP(I34,Map!$F$18:$H$51,3,0) -> Variable | X34: Pending | Y34: =VLOOKUP(L34,Map!$C$18:$D$29,2,0) -> GLT | AA34: =IF(Y34="TOTAL",(Z34*0.19),0) -> 0 | AB34: =Z34*1.19 -> 0 | AC34: =Z34/S34 -> 0 | AD34: =IF(Y34="TOTAL",(AC34*0.19),0) -> 0 | AE34: =AC34*1.19 -> 0
B35: 2026 | C35: Jun27 to Jul15 | D35: JUL | E35: JUL (Provision) | F35: Pending | I35: PARIS (FULLKOM) | J35: =IFERROR(VLOOKUP(I35,Map!$F$18:$G$56,2,0),"Add in Map") -> 3P | K35: =VLOOKUP(L35,Map!$C$18:$D$29,2,0) -> PNT | L35: Audio | M35: 374175.99 | N35: =IF(L35="TOTAL",(M35*0.19),0) -> 0 | O35: =M35*1.19 -> 445269.43 | P35: =M35/S35 -> 404.95237 | Q35: =IF(L35="TOTAL",(P35*0.19),0) -> 0 | R35: =P35*1.19 -> 481.89333 | S35: =INDEX(FX!$D$3:$O$19,MATCH(B35,FX!$B$3:$B$32,0),MATCH(D35,FX!$D$2:$O$2,0)) -> 924 | T35: Commission (1era Quincena) | U35: Provision (Based on PO, One View) | V35: Invoice | W35: =VLOOKUP(I35,Map!$F$18:$H$51,3,0) -> Variable | X35: Pending | Y35: =VLOOKUP(L35,Map!$C$18:$D$29,2,0) -> PNT | AA35: =IF(Y35="TOTAL",(Z35*0.19),0) -> 0 | AB35: =Z35*1.19 -> 0 | AC35: =Z35/S35 -> 0 | AD35: =IF(Y35="TOTAL",(AC35*0.19),0) -> 0 | AE35: =AC35*1.19 -> 0
B36: 2026 | C36: Jun27 to Jul15 | D36: JUL | E36: JUL (Provision) | F36: Pending | I36: PARIS (FULLKOM) | J36: =IFERROR(VLOOKUP(I36,Map!$F$18:$G$56,2,0),"Add in Map") -> 3P | K36: =VLOOKUP(L36,Map!$C$18:$D$29,2,0) -> GTT | L36: Monitor | M36: 213814.85 | N36: =IF(L36="TOTAL",(M36*0.19),0) -> 0 | O36: =M36*1.19 -> 254439.68 | P36: =M36/S36 -> 231.40136 | Q36: =IF(L36="TOTAL",(P36*0.19),0) -> 0 | R36: =P36*1.19 -> 275.36761 | S36: =INDEX(FX!$D$3:$O$19,MATCH(B36,FX!$B$3:$B$32,0),MATCH(D36,FX!$D$2:$O$2,0)) -> 924 | T36: Commission (1era Quincena) | U36: Provision (Based on PO, One View) | V36: Invoice | W36: =VLOOKUP(I36,Map!$F$18:$H$51,3,0) -> Variable | X36: Pending | Y36: =VLOOKUP(L36,Map!$C$18:$D$29,2,0) -> GTT | AA36: =IF(Y36="TOTAL",(Z36*0.19),0) -> 0 | AB36: =Z36*1.19 -> 0 | AC36: =Z36/S36 -> 0 | AD36: =IF(Y36="TOTAL",(AC36*0.19),0) -> 0 | AE36: =AC36*1.19 -> 0
B37: 2026 | C37: Jun27 to Jul15 | D37: JUL | E37: JUL (Provision) | F37: Pending | I37: PARIS (FULLKOM) | J37: =IFERROR(VLOOKUP(I37,Map!$F$18:$G$56,2,0),"Add in Map") -> 3P | K37: =VLOOKUP(L37,Map!$C$18:$D$29,2,0) -> DGT | L37: RAC | M37: 160361.14 | N37: =IF(L37="TOTAL",(M37*0.19),0) -> 0 | O37: =M37*1.19 -> 190829.76 | P37: =M37/S37 -> 173.55102 | Q37: =IF(L37="TOTAL",(P37*0.19),0) -> 0 | R37: =P37*1.19 -> 206.52571 | S37: =INDEX(FX!$D$3:$O$19,MATCH(B37,FX!$B$3:$B$32,0),MATCH(D37,FX!$D$2:$O$2,0)) -> 924 | T37: Commission (1era Quincena) | U37: Provision (Based on PO, One View) | V37: Invoice | W37: =VLOOKUP(I37,Map!$F$18:$H$51,3,0) -> Variable | X37: Pending | Y37: =VLOOKUP(L37,Map!$C$18:$D$29,2,0) -> DGT | AA37: =IF(Y37="TOTAL",(Z37*0.19),0) -> 0 | AB37: =Z37*1.19 -> 0 | AC37: =Z37/S37 -> 0 | AD37: =IF(Y37="TOTAL",(AC37*0.19),0) -> 0 | AE37: =AC37*1.19 -> 0
B38: 2026 | C38: Jun27 to Jul15 | D38: JUL | E38: JUL (Provision) | F38: Pending | I38: PARIS (FULLKOM) | J38: =IFERROR(VLOOKUP(I38,Map!$F$18:$G$56,2,0),"Add in Map") -> 3P | K38: =VLOOKUP(L38,Map!$C$18:$D$29,2,0) -> DLT | L38: Air Cleaner | M38: 53453.713 | N38: =IF(L38="TOTAL",(M38*0.19),0) -> 0 | O38: =M38*1.19 -> 63609.919 | P38: =M38/S38 -> 57.850339 | Q38: =IF(L38="TOTAL",(P38*0.19),0) -> 0 | R38: =P38*1.19 -> 68.841904 | S38: =INDEX(FX!$D$3:$O$19,MATCH(B38,FX!$B$3:$B$32,0),MATCH(D38,FX!$D$2:$O$2,0)) -> 924 | T38: Commission (1era Quincena) | U38: Provision (Based on PO, One View) | V38: Invoice | W38: =VLOOKUP(I38,Map!$F$18:$H$51,3,0) -> Variable | X38: Pending | Y38: =VLOOKUP(L38,Map!$C$18:$D$29,2,0) -> DLT | AA38: =IF(Y38="TOTAL",(Z38*0.19),0) -> 0 | AB38: =Z38*1.19 -> 0 | AC38: =Z38/S38 -> 0 | AD38: =IF(Y38="TOTAL",(AC38*0.19),0) -> 0 | AE38: =AC38*1.19 -> 0
B39: 2026 | C39: Jun27 to Jul15 | D39: JUL | E39: JUL (Provision) | F39: Pending | I39: PARIS (FULLKOM) | J39: =IFERROR(VLOOKUP(I39,Map!$F$18:$G$56,2,0),"Add in Map") -> 3P | K39: =VLOOKUP(L39,Map!$C$18:$D$29,2,0) -> DMT | L39: SAC | M39: 0 | N39: =IF(L39="TOTAL",(M39*0.19),0) -> 0 | O39: =M39*1.19 -> 0 | P39: =M39/S39 -> 0 | Q39: =IF(L39="TOTAL",(P39*0.19),0) -> 0 | R39: =P39*1.19 -> 0 | S39: =INDEX(FX!$D$3:$O$19,MATCH(B39,FX!$B$3:$B$32,0),MATCH(D39,FX!$D$2:$O$2,0)) -> 924 | T39: Commission (1era Quincena) | U39: Provision (Based on PO, One View) | V39: Invoice | W39: =VLOOKUP(I39,Map!$F$18:$H$51,3,0) -> Variable | X39: Pending | Y39: =VLOOKUP(L39,Map!$C$18:$D$29,2,0) -> DMT | AA39: =IF(Y39="TOTAL",(Z39*0.19),0) -> 0 | AB39: =Z39*1.19 -> 0 | AC39: =Z39/S39 -> 0 | AD39: =IF(Y39="TOTAL",(AC39*0.19),0) -> 0 | AE39: =AC39*1.19 -> 0
B40: 2026 | C40: Jun27 to Jul15 | D40: JUL | E40: JUL (Provision) | F40: Pending | I40: PARIS (FULLKOM) | J40: =IFERROR(VLOOKUP(I40,Map!$F$18:$G$56,2,0),"Add in Map") -> 3P | K40: =VLOOKUP(L40,Map!$C$18:$D$29,2,0) -> TOTAL | L40: TOTAL | M40: =SUM(M29:M39) -> 17265549 | N40: =IF(L40="TOTAL",(M40*0.19),0) -> 3280454.4 | O40: =M40*1.19 -> 20546004 | P40: =M40/S40 -> 18685.66 | Q40: =IF(L40="TOTAL",(P40*0.19),0) -> 3550.2753 | R40: =P40*1.19 -> 22235.935 | S40: =INDEX(FX!$D$3:$O$19,MATCH(B40,FX!$B$3:$B$32,0),MATCH(D40,FX!$D$2:$O$2,0)) -> 924 | T40: Commission (1era Quincena) | U40: Provision (Based on PO, One View) | V40: Invoice | W40: =VLOOKUP(I40,Map!$F$18:$H$51,3,0) -> Variable | X40: Pending | Y40: =VLOOKUP(L40,Map!$C$18:$D$29,2,0) -> TOTAL | AA40: =IF(Y40="TOTAL",(Z40*0.19),0) -> 0 | AB40: =Z40*1.19 -> 0 | AC40: =Z40/S40 -> 0 | AD40: =IF(Y40="TOTAL",(AC40*0.19),0) -> 0 | AE40: =AC40*1.19 -> 0
B41: 2026 | C41: Jul16 to Jul31 | D41: JUL | E41: JUL (Provision) | F41: Pending | I41: PARIS (FULLKOM) | J41: =IFERROR(VLOOKUP(I41,Map!$F$18:$G$56,2,0),"Add in Map") -> 3P | K41: =VLOOKUP(L41,Map!$C$18:$D$29,2,0) -> CNT | L41: Refrigeration | M41: 4054902.2 | N41: =IF(L41="TOTAL",(M41*0.19),0) -> 0 | O41: =M41*1.19 -> 4825333.7 | P41: =M41/S41 -> 4388.4223 | Q41: =IF(L41="TOTAL",(P41*0.19),0) -> 0 | R41: =P41*1.19 -> 5222.2226 | S41: =INDEX(FX!$D$3:$O$19,MATCH(B41,FX!$B$3:$B$32,0),MATCH(D41,FX!$D$2:$O$2,0)) -> 924 | T41: Commission (2da Quincena) | U41: Provision (Based on PO, One View) | V41: Invoice | W41: =VLOOKUP(I41,Map!$F$18:$H$51,3,0) -> Variable | X41: Pending | Y41: =VLOOKUP(L41,Map!$C$18:$D$29,2,0) -> CNT | AA41: =IF(Y41="TOTAL",(Z41*0.19),0) -> 0 | AB41: =Z41*1.19 -> 0 | AC41: =Z41/S41 -> 0 | AD41: =IF(Y41="TOTAL",(AC41*0.19),0) -> 0 | AE41: =AC41*1.19 -> 0
B42: 2026 | C42: Jul16 to Jul31 | D42: JUL | E42: JUL (Provision) | F42: Pending | I42: PARIS (FULLKOM) | J42: =IFERROR(VLOOKUP(I42,Map!$F$18:$G$56,2,0),"Add in Map") -> 3P | K42: =VLOOKUP(L42,Map!$C$18:$D$29,2,0) -> CVT | L42: Cooking | M42: 0 | N42: =IF(L42="TOTAL",(M42*0.19),0) -> 0 | O42: =M42*1.19 -> 0 | P42: =M42/S42 -> 0 | Q42: =IF(L42="TOTAL",(P42*0.19),0) -> 0 | R42: =P42*1.19 -> 0 | S42: =INDEX(FX!$D$3:$O$19,MATCH(B42,FX!$B$3:$B$32,0),MATCH(D42,FX!$D$2:$O$2,0)) -> 924 | T42: Commission (2da Quincena) | U42: Provision (Based on PO, One View) | V42: Invoice | W42: =VLOOKUP(I42,Map!$F$18:$H$51,3,0) -> Variable | X42: Pending | Y42: =VLOOKUP(L42,Map!$C$18:$D$29,2,0) -> CVT | AA42: =IF(Y42="TOTAL",(Z42*0.19),0) -> 0 | AB42: =Z42*1.19 -> 0 | AC42: =Z42/S42 -> 0 | AD42: =IF(Y42="TOTAL",(AC42*0.19),0) -> 0 | AE42: =AC42*1.19 -> 0
...

Sheet Master 1_BU v2
D2: Incluir al final toda la info de Map2
B4: Year | C4: Cut Date | D4: Invoice Received | E4: Impact Month | F4: Invoice Registered | G4: Invoice Date | H4: Invoice Number | I4: Customer | J4: OBS/3P | K4: BU | L4: Division | M4: Invoice Net Amt (CLP) | N4: VAT (CLP) | O4: Total Amt (CLP) | P4: Invoice Net Amt (USD) | Q4: VAT (USD) | R4: Total Amt (USD) | S4: FX Rate | T4: Commission Type | U4: Provision | V4: Doc Type | W4: Variable /Fixed | X4: Invoice Status | Y4: BU | Z4: Provision Net Amt (CLP) | AA4: Provision VAT (CLP) | AB4: Provision Amt (CLP) | AC4: Provision Net Amt (USD) | AD4: Provision VAT (USD) | AE4: Provision Amt (USD) | AF4: Invoice URL
B5: 2026 | C5: JUN 21 to JUL 20 | D5: JUL | E5: JUL (Provision) | F5: AUG | G5: 46230 | H5: 478270 | I5: FALABELLA (DIRECT) | J5: =IFERROR(VLOOKUP(I5,Map!$F$18:$G$56,2,0),"Add in Map") -> 3P | K5: =VLOOKUP(L5,Map!$C$18:$D$29,2,0) -> CNT | L5: Refrigeration | M5: 24645503 | N5: =IF(L5="TOTAL",(M5*0.19),0) -> 0 | O5: =M5*1.19 -> 29328148 | P5: =M5/S5 -> 26672.622 | Q5: =IF(L5="TOTAL",(P5*0.19),0) -> 0 | R5: =P5*1.19 -> 31740.42 | S5: =INDEX(FX!$D$3:$O$19,MATCH(B5,FX!$B$3:$B$32,0),MATCH(D5,FX!$D$2:$O$2,0)) -> 924 | T5: Monthly Commission | U5: Provision (Based on External Report) | V5: Invoice | W5: =VLOOKUP(I5,Map!$F$18:$H$51,3,0) -> Variable | X5: AP Completed | Y5: =VLOOKUP(L5,Map!$C$18:$D$29,2,0) -> CNT | Z5: 24645503 | AA5: =IF(Y5="TOTAL",(Z5*0.19),0) -> 0 | AB5: =Z5*1.19 -> 29328148 | AC5: =Z5/S5 -> 26672.622 | AD5: =IF(Y5="TOTAL",(AC5*0.19),0) -> 0 | AE5: =AC5*1.19 -> 31740.42
B6: 2026 | C6: JUN 21 to JUL 20 | D6: JUL | E6: JUL (Provision) | F6: AUG | G6: 46230 | H6: 478270 | I6: FALABELLA (DIRECT) | J6: =IFERROR(VLOOKUP(I6,Map!$F$18:$G$56,2,0),"Add in Map") -> 3P | K6: =VLOOKUP(L6,Map!$C$18:$D$29,2,0) -> CVT | L6: Cooking | M6: 291662.76 | N6: =IF(L6="TOTAL",(M6*0.19),0) -> 0 | O6: =M6*1.19 -> 347078.68 | P6: =M6/S6 -> 315.65233 | Q6: =IF(L6="TOTAL",(P6*0.19),0) -> 0 | R6: =P6*1.19 -> 375.62628 | S6: =INDEX(FX!$D$3:$O$19,MATCH(B6,FX!$B$3:$B$32,0),MATCH(D6,FX!$D$2:$O$2,0)) -> 924 | T6: Monthly Commission | U6: Provision (Based on External Report) | V6: Invoice | W6: =VLOOKUP(I6,Map!$F$18:$H$51,3,0) -> Variable | X6: AP Completed | Y6: =VLOOKUP(L6,Map!$C$18:$D$29,2,0) -> CVT | Z6: 291662.76 | AA6: =IF(Y6="TOTAL",(Z6*0.19),0) -> 0 | AB6: =Z6*1.19 -> 347078.68 | AC6: =Z6/S6 -> 315.65233 | AD6: =IF(Y6="TOTAL",(AC6*0.19),0) -> 0 | AE6: =AC6*1.19 -> 375.62628
B7: 2026 | C7: JUN 21 to JUL 20 | D7: JUL | E7: JUL (Provision) | F7: AUG | G7: 46230 | H7: 478270 | I7: FALABELLA (DIRECT) | J7: =IFERROR(VLOOKUP(I7,Map!$F$18:$G$56,2,0),"Add in Map") -> 3P | K7: =VLOOKUP(L7,Map!$C$18:$D$29,2,0) -> CDT | L7: Dishwasher | M7: 1020819.6 | N7: =IF(L7="TOTAL",(M7*0.19),0) -> 0 | O7: =M7*1.19 -> 1214775.4 | P7: =M7/S7 -> 1104.7832 | Q7: =IF(L7="TOTAL",(P7*0.19),0) -> 0 | R7: =P7*1.19 -> 1314.692 | S7: =INDEX(FX!$D$3:$O$19,MATCH(B7,FX!$B$3:$B$32,0),MATCH(D7,FX!$D$2:$O$2,0)) -> 924 | T7: Monthly Commission | U7: Provision (Based on External Report) | V7: Invoice | W7: =VLOOKUP(I7,Map!$F$18:$H$51,3,0) -> Variable | X7: AP Completed | Y7: =VLOOKUP(L7,Map!$C$18:$D$29,2,0) -> CDT | Z7: 1020819.6 | AA7: =IF(Y7="TOTAL",(Z7*0.19),0) -> 0 | AB7: =Z7*1.19 -> 1214775.4 | AC7: =Z7/S7 -> 1104.7832 | AD7: =IF(Y7="TOTAL",(AC7*0.19),0) -> 0 | AE7: =AC7*1.19 -> 1314.692
B8: 2026 | C8: JUN 21 to JUL 20 | D8: JUL | E8: JUL (Provision) | F8: AUG | G8: 46230 | H8: 478270 | I8: FALABELLA (DIRECT) | J8: =IFERROR(VLOOKUP(I8,Map!$F$18:$G$56,2,0),"Add in Map") -> 3P | K8: =VLOOKUP(L8,Map!$C$18:$D$29,2,0) -> DFT | L8: WM | M8: 73207352 | N8: =IF(L8="TOTAL",(M8*0.19),0) -> 0 | O8: =M8*1.19 -> 87116749 | P8: =M8/S8 -> 79228.736 | Q8: =IF(L8="TOTAL",(P8*0.19),0) -> 0 | R8: =P8*1.19 -> 94282.196 | S8: =INDEX(FX!$D$3:$O$19,MATCH(B8,FX!$B$3:$B$32,0),MATCH(D8,FX!$D$2:$O$2,0)) -> 924 | T8: Monthly Commission | U8: Provision (Based on External Report) | V8: Invoice | W8: =VLOOKUP(I8,Map!$F$18:$H$51,3,0) -> Variable | X8: AP Completed | Y8: =VLOOKUP(L8,Map!$C$18:$D$29,2,0) -> DFT | Z8: 73207352 | AA8: =IF(Y8="TOTAL",(Z8*0.19),0) -> 0 | AB8: =Z8*1.19 -> 87116749 | AC8: =Z8/S8 -> 79228.736 | AD8: =IF(Y8="TOTAL",(AC8*0.19),0) -> 0 | AE8: =AC8*1.19 -> 94282.196
B9: 2026 | C9: JUN 21 to JUL 20 | D9: JUL | E9: JUL (Provision) | F9: AUG | G9: 46230 | H9: 478270 | I9: FALABELLA (DIRECT) | J9: =IFERROR(VLOOKUP(I9,Map!$F$18:$G$56,2,0),"Add in Map") -> 3P | K9: =VLOOKUP(L9,Map!$C$18:$D$29,2,0) -> DVT | L9: VCC | M9: 145831.38 | N9: =IF(L9="TOTAL",(M9*0.19),0) -> 0 | O9: =M9*1.19 -> 173539.34 | P9: =M9/S9 -> 157.82617 | Q9: =IF(L9="TOTAL",(P9*0.19),0) -> 0 | R9: =P9*1.19 -> 187.81314 | S9: =INDEX(FX!$D$3:$O$19,MATCH(B9,FX!$B$3:$B$32,0),MATCH(D9,FX!$D$2:$O$2,0)) -> 924 | T9: Monthly Commission | U9: Provision (Based on External Report) | V9: Invoice | W9: =VLOOKUP(I9,Map!$F$18:$H$51,3,0) -> Variable | X9: AP Completed | Y9: =VLOOKUP(L9,Map!$C$18:$D$29,2,0) -> DVT | Z9: 145831.38 | AA9: =IF(Y9="TOTAL",(Z9*0.19),0) -> 0 | AB9: =Z9*1.19 -> 173539.34 | AC9: =Z9/S9 -> 157.82617 | AD9: =IF(Y9="TOTAL",(AC9*0.19),0) -> 0 | AE9: =AC9*1.19 -> 187.81314
B10: 2026 | C10: JUN 21 to JUL 20 | D10: JUL | E10: JUL (Provision) | F10: AUG | G10: 46230 | H10: 478270 | I10: FALABELLA (DIRECT) | J10: =IFERROR(VLOOKUP(I10,Map!$F$18:$G$56,2,0),"Add in Map") -> 3P | K10: =VLOOKUP(L10,Map!$C$18:$D$29,2,0) -> GLT | L10: Television | M10: 34707868 | N10: =IF(L10="TOTAL",(M10*0.19),0) -> 0 | O10: =M10*1.19 -> 41302363 | P10: =M10/S10 -> 37562.628 | Q10: =IF(L10="TOTAL",(P10*0.19),0) -> 0 | R10: =P10*1.19 -> 44699.527 | S10: =INDEX(FX!$D$3:$O$19,MATCH(B10,FX!$B$3:$B$32,0),MATCH(D10,FX!$D$2:$O$2,0)) -> 924 | T10: Monthly Commission | U10: Provision (Based on External Report) | V10: Invoice | W10: =VLOOKUP(I10,Map!$F$18:$H$51,3,0) -> Variable | X10: AP Completed | Y10: =VLOOKUP(L10,Map!$C$18:$D$29,2,0) -> GLT | Z10: 34707868 | AA10: =IF(Y10="TOTAL",(Z10*0.19),0) -> 0 | AB10: =Z10*1.19 -> 41302363 | AC10: =Z10/S10 -> 37562.628 | AD10: =IF(Y10="TOTAL",(AC10*0.19),0) -> 0 | AE10: =AC10*1.19 -> 44699.527
B11: 2026 | C11: JUN 21 to JUL 20 | D11: JUL | E11: JUL (Provision) | F11: AUG | G11: 46230 | H11: 478270 | I11: FALABELLA (DIRECT) | J11: =IFERROR(VLOOKUP(I11,Map!$F$18:$G$56,2,0),"Add in Map") -> 3P | K11: =VLOOKUP(L11,Map!$C$18:$D$29,2,0) -> PNT | L11: Audio | M11: 2187470.7 | N11: =IF(L11="TOTAL",(M11*0.19),0) -> 0 | O11: =M11*1.19 -> 2603090.1 | P11: =M11/S11 -> 2367.3925 | Q11: =IF(L11="TOTAL",(P11*0.19),0) -> 0 | R11: =P11*1.19 -> 2817.1971 | S11: =INDEX(FX!$D$3:$O$19,MATCH(B11,FX!$B$3:$B$32,0),MATCH(D11,FX!$D$2:$O$2,0)) -> 924 | T11: Monthly Commission | U11: Provision (Based on External Report) | V11: Invoice | W11: =VLOOKUP(I11,Map!$F$18:$H$51,3,0) -> Variable | X11: AP Completed | Y11: =VLOOKUP(L11,Map!$C$18:$D$29,2,0) -> PNT | Z11: 2187470.7 | AA11: =IF(Y11="TOTAL",(Z11*0.19),0) -> 0 | AB11: =Z11*1.19 -> 2603090.1 | AC11: =Z11/S11 -> 2367.3925 | AD11: =IF(Y11="TOTAL",(AC11*0.19),0) -> 0 | AE11: =AC11*1.19 -> 2817.1971
B12: 2026 | C12: JUN 21 to JUL 20 | D12: JUL | E12: JUL (Provision) | F12: AUG | G12: 46230 | H12: 478270 | I12: FALABELLA (DIRECT) | J12: =IFERROR(VLOOKUP(I12,Map!$F$18:$G$56,2,0),"Add in Map") -> 3P | K12: =VLOOKUP(L12,Map!$C$18:$D$29,2,0) -> GTT | L12: Monitor | M12: 3645784.5 | N12: =IF(L12="TOTAL",(M12*0.19),0) -> 0 | O12: =M12*1.19 -> 4338483.5 | P12: =M12/S12 -> 3945.6542 | Q12: =IF(L12="TOTAL",(P12*0.19),0) -> 0 | R12: =P12*1.19 -> 4695.3285 | S12: =INDEX(FX!$D$3:$O$19,MATCH(B12,FX!$B$3:$B$32,0),MATCH(D12,FX!$D$2:$O$2,0)) -> 924 | T12: Monthly Commission | U12: Provision (Based on External Report) | V12: Invoice | W12: =VLOOKUP(I12,Map!$F$18:$H$51,3,0) -> Variable | X12: AP Completed | Y12: =VLOOKUP(L12,Map!$C$18:$D$29,2,0) -> GTT | Z12: 3645784.5 | AA12: =IF(Y12="TOTAL",(Z12*0.19),0) -> 0 | AB12: =Z12*1.19 -> 4338483.5 | AC12: =Z12/S12 -> 3945.6542 | AD12: =IF(Y12="TOTAL",(AC12*0.19),0) -> 0 | AE12: =AC12*1.19 -> 4695.3285
B13: 2026 | C13: JUN 21 to JUL 20 | D13: JUL | E13: JUL (Provision) | F13: AUG | G13: 46230 | H13: 478270 | I13: FALABELLA (DIRECT) | J13: =IFERROR(VLOOKUP(I13,Map!$F$18:$G$56,2,0),"Add in Map") -> 3P | K13: =VLOOKUP(L13,Map!$C$18:$D$29,2,0) -> DGT | L13: RAC | M13: 1020819.6 | N13: =IF(L13="TOTAL",(M13*0.19),0) -> 0 | O13: =M13*1.19 -> 1214775.4 | P13: =M13/S13 -> 1104.7832 | Q13: =IF(L13="TOTAL",(P13*0.19),0) -> 0 | R13: =P13*1.19 -> 1314.692 | S13: =INDEX(FX!$D$3:$O$19,MATCH(B13,FX!$B$3:$B$32,0),MATCH(D13,FX!$D$2:$O$2,0)) -> 924 | T13: Monthly Commission | U13: Provision (Based on External Report) | V13: Invoice | W13: =VLOOKUP(I13,Map!$F$18:$H$51,3,0) -> Variable | X13: AP Completed | Y13: =VLOOKUP(L13,Map!$C$18:$D$29,2,0) -> DGT | Z13: 1020819.6 | AA13: =IF(Y13="TOTAL",(Z13*0.19),0) -> 0 | AB13: =Z13*1.19 -> 1214775.4 | AC13: =Z13/S13 -> 1104.7832 | AD13: =IF(Y13="TOTAL",(AC13*0.19),0) -> 0 | AE13: =AC13*1.19 -> 1314.692
B14: 2026 | C14: JUN 21 to JUL 20 | D14: JUL | E14: JUL (Provision) | F14: AUG | G14: 46230 | H14: 478270 | I14: FALABELLA (DIRECT) | J14: =IFERROR(VLOOKUP(I14,Map!$F$18:$G$56,2,0),"Add in Map") -> 3P | K14: =VLOOKUP(L14,Map!$C$18:$D$29,2,0) -> DLT | L14: Air Cleaner | M14: 291662.76 | N14: =IF(L14="TOTAL",(M14*0.19),0) -> 0 | O14: =M14*1.19 -> 347078.68 | P14: =M14/S14 -> 315.65233 | Q14: =IF(L14="TOTAL",(P14*0.19),0) -> 0 | R14: =P14*1.19 -> 375.62628 | S14: =INDEX(FX!$D$3:$O$19,MATCH(B14,FX!$B$3:$B$32,0),MATCH(D14,FX!$D$2:$O$2,0)) -> 924 | T14: Monthly Commission | U14: Provision (Based on External Report) | V14: Invoice | W14: =VLOOKUP(I14,Map!$F$18:$H$51,3,0) -> Variable | X14: AP Completed | Y14: =VLOOKUP(L14,Map!$C$18:$D$29,2,0) -> DLT | Z14: 291662.76 | AA14: =IF(Y14="TOTAL",(Z14*0.19),0) -> 0 | AB14: =Z14*1.19 -> 347078.68 | AC14: =Z14/S14 -> 315.65233 | AD14: =IF(Y14="TOTAL",(AC14*0.19),0) -> 0 | AE14: =AC14*1.19 -> 375.62628
B15: 2026 | C15: JUN 21 to JUL 20 | D15: JUL | E15: JUL (Provision) | F15: AUG | G15: 46230 | H15: 478270 | I15: FALABELLA (DIRECT) | J15: =IFERROR(VLOOKUP(I15,Map!$F$18:$G$56,2,0),"Add in Map") -> 3P | K15: =VLOOKUP(L15,Map!$C$18:$D$29,2,0) -> DMT | L15: SAC | M15: 0 | N15: =IF(L15="TOTAL",(M15*0.19),0) -> 0 | O15: =M15*1.19 -> 0 | P15: 0 | Q15: =IF(L15="TOTAL",(P15*0.19),0) -> 0 | R15: =P15*1.19 -> 0 | S15: =INDEX(FX!$D$3:$O$19,MATCH(B15,FX!$B$3:$B$32,0),MATCH(D15,FX!$D$2:$O$2,0)) -> 924 | T15: Monthly Commission | U15: Provision (Based on External Report) | V15: Invoice | W15: =VLOOKUP(I15,Map!$F$18:$H$51,3,0) -> Variable | X15: AP Completed | Y15: =VLOOKUP(L15,Map!$C$18:$D$29,2,0) -> DMT | Z15: 0 | AA15: =IF(Y15="TOTAL",(Z15*0.19),0) -> 0 | AB15: =Z15*1.19 -> 0 | AC15: =Z15/S15 -> 0 | AD15: =IF(Y15="TOTAL",(AC15*0.19),0) -> 0 | AE15: =AC15*1.19 -> 0
B16: 2026 | C16: JUN 21 to JUL 20 | D16: JUL | E16: JUL (Provision) | F16: AUG | G16: 46230 | H16: 478270 | I16: FALABELLA (DIRECT) | J16: =IFERROR(VLOOKUP(I16,Map!$F$18:$G$56,2,0),"Add in Map") -> 3P | K16: =VLOOKUP(L16,Map!$C$18:$D$29,2,0) -> TOTAL | L16: TOTAL | M16: =SUM(M5:M15) -> 141164774 | N16: =IF(L16="TOTAL",(M16*0.19),0) -> 26821307 | O16: =M16*1.19 -> 1.6798608e+08 | P16: =M16/S16 -> 152775.73 | Q16: =IF(L16="TOTAL",(P16*0.19),0) -> 29027.389 | R16: =P16*1.19 -> 181803.12 | S16: =INDEX(FX!$D$3:$O$19,MATCH(B16,FX!$B$3:$B$32,0),MATCH(D16,FX!$D$2:$O$2,0)) -> 924 | T16: Monthly Commission | U16: Provision (Based on External Report) | V16: Invoice | W16: =VLOOKUP(I16,Map!$F$18:$H$51,3,0) -> Variable | X16: AP Completed | Y16: =VLOOKUP(L16,Map!$C$18:$D$29,2,0) -> TOTAL | Z16: =SUM(Z5:Z15) -> 141164774 | AA16: =IF(Y16="TOTAL",(Z16*0.19),0) -> 26821307 | AB16: =Z16*1.19 -> 1.6798608e+08 | AC16: =Z16/S16 -> 152775.73 | AD16: =IF(Y16="TOTAL",(AC16*0.19),0) -> 29027.389 | AE16: =AC16*1.19 -> 181803.12 | AF16: http://lg2607.acepta.com/v01/5E0A125A9F4EB54908C00523002399A4BD42D7F9
B17: 2026 | C17: JUN 21 to JUL 20 | D17: JUL | E17: JUL (Provision) | F17: AUG | G17: 46230 | H17: 456288 | I17: FALABELLA (DIRECT) | J17: =IFERROR(VLOOKUP(I17,Map!$F$18:$G$56,2,0),"Add in Map") -> 3P | K17: =VLOOKUP(L17,Map!$C$18:$D$29,2,0) -> CNT | L17: Refrigeration | M17: -10338484 | N17: =IF(L17="TOTAL",(M17*0.19),0) -> 0 | O17: =M17*1.19 -> -12302795 | P17: =M17/S17 -> -11188.835 | Q17: =IF(L17="TOTAL",(P17*0.19),0) -> 0 | R17: =P17*1.19 -> -13314.714 | S17: =INDEX(FX!$D$3:$O$19,MATCH(B17,FX!$B$3:$B$32,0),MATCH(D17,FX!$D$2:$O$2,0)) -> 924 | T17: Monthly Commission | U17: Provision (Based on External Report) | V17: Credit Note | W17: =VLOOKUP(I17,Map!$F$18:$H$51,3,0) -> Variable | X17: AP Completed | Y17: =VLOOKUP(L17,Map!$C$18:$D$29,2,0) -> CNT | Z17: -10338484 | AA17: =IF(Y17="TOTAL",(Z17*0.19),0) -> 0 | AB17: =Z17*1.19 -> -12302795 | AC17: =Z17/S17 -> -11188.835 | AD17: =IF(Y17="TOTAL",(AC17*0.19),0) -> 0 | AE17: =AC17*1.19 -> -13314.714
B18: 2026 | C18: JUN 21 to JUL 20 | D18: JUL | E18: JUL (Provision) | F18: AUG | G18: 46230 | H18: 456288 | I18: FALABELLA (DIRECT) | J18: =IFERROR(VLOOKUP(I18,Map!$F$18:$G$56,2,0),"Add in Map") -> 3P | K18: =VLOOKUP(L18,Map!$C$18:$D$29,2,0) -> CVT | L18: Cooking | M18: -122348.92 | N18: =IF(L18="TOTAL",(M18*0.19),0) -> 0 | O18: =M18*1.19 -> -145595.21 | P18: =M18/S18 -> -132.41225 | Q18: =IF(L18="TOTAL",(P18*0.19),0) -> 0 | R18: =P18*1.19 -> -157.57058 | S18: =INDEX(FX!$D$3:$O$19,MATCH(B18,FX!$B$3:$B$32,0),MATCH(D18,FX!$D$2:$O$2,0)) -> 924 | T18: Monthly Commission | U18: Provision (Based on External Report) | V18: Credit Note | W18: =VLOOKUP(I18,Map!$F$18:$H$51,3,0) -> Variable | X18: AP Completed | Y18: =VLOOKUP(L18,Map!$C$18:$D$29,2,0) -> CVT | Z18: -122348.92 | AA18: =IF(Y18="TOTAL",(Z18*0.19),0) -> 0 | AB18: =Z18*1.19 -> -145595.21 | AC18: =Z18/S18 -> -132.41225 | AD18: =IF(Y18="TOTAL",(AC18*0.19),0) -> 0 | AE18: =AC18*1.19 -> -157.57058
B19: 2026 | C19: JUN 21 to JUL 20 | D19: JUL | E19: JUL (Provision) | F19: AUG | G19: 46230 | H19: 456288 | I19: FALABELLA (DIRECT) | J19: =IFERROR(VLOOKUP(I19,Map!$F$18:$G$56,2,0),"Add in Map") -> 3P | K19: =VLOOKUP(L19,Map!$C$18:$D$29,2,0) -> CDT | L19: Dishwasher | M19: -428221.21 | N19: =IF(L19="TOTAL",(M19*0.19),0) -> 0 | O19: =M19*1.19 -> -509583.24 | P19: =M19/S19 -> -463.44287 | Q19: =IF(L19="TOTAL",(P19*0.19),0) -> 0 | R19: =P19*1.19 -> -551.49701 | S19: =INDEX(FX!$D$3:$O$19,MATCH(B19,FX!$B$3:$B$32,0),MATCH(D19,FX!$D$2:$O$2,0)) -> 924 | T19: Monthly Commission | U19: Provision (Based on External Report) | V19: Credit Note | W19: =VLOOKUP(I19,Map!$F$18:$H$51,3,0) -> Variable | X19: AP Completed | Y19: =VLOOKUP(L19,Map!$C$18:$D$29,2,0) -> CDT | Z19: -428221.21 | AA19: =IF(Y19="TOTAL",(Z19*0.19),0) -> 0 | AB19: =Z19*1.19 -> -509583.24 | AC19: =Z19/S19 -> -463.44287 | AD19: =IF(Y19="TOTAL",(AC19*0.19),0) -> 0 | AE19: =AC19*1.19 -> -551.49701
B20: 2026 | C20: JUN 21 to JUL 20 | D20: JUL | E20: JUL (Provision) | F20: AUG | G20: 46230 | H20: 456288 | I20: FALABELLA (DIRECT) | J20: =IFERROR(VLOOKUP(I20,Map!$F$18:$G$56,2,0),"Add in Map") -> 3P | K20: =VLOOKUP(L20,Map!$C$18:$D$29,2,0) -> DFT | L20: WM | M20: -30709578 | N20: =IF(L20="TOTAL",(M20*0.19),0) -> 0 | O20: =M20*1.19 -> -36544398 | P20: =M20/S20 -> -33235.474 | Q20: =IF(L20="TOTAL",(P20*0.19),0) -> 0 | R20: =P20*1.19 -> -39550.214 | S20: =INDEX(FX!$D$3:$O$19,MATCH(B20,FX!$B$3:$B$32,0),MATCH(D20,FX!$D$2:$O$2,0)) -> 924 | T20: Monthly Commission | U20: Provision (Based on External Report) | V20: Credit Note | W20: =VLOOKUP(I20,Map!$F$18:$H$51,3,0) -> Variable | X20: AP Completed | Y20: =VLOOKUP(L20,Map!$C$18:$D$29,2,0) -> DFT | Z20: -30709578 | AA20: =IF(Y20="TOTAL",(Z20*0.19),0) -> 0 | AB20: =Z20*1.19 -> -36544398 | AC20: =Z20/S20 -> -33235.474 | AD20: =IF(Y20="TOTAL",(AC20*0.19),0) -> 0 | AE20: =AC20*1.19 -> -39550.214
B21: 2026 | C21: JUN 21 to JUL 20 | D21: JUL | E21: JUL (Provision) | F21: AUG | G21: 46230 | H21: 456288 | I21: FALABELLA (DIRECT) | J21: =IFERROR(VLOOKUP(I21,Map!$F$18:$G$56,2,0),"Add in Map") -> 3P | K21: =VLOOKUP(L21,Map!$C$18:$D$29,2,0) -> DVT | L21: VCC | M21: -61174.459 | N21: =IF(L21="TOTAL",(M21*0.19),0) -> 0 | O21: =M21*1.19 -> -72797.606 | P21: =M21/S21 -> -66.206124 | Q21: =IF(L21="TOTAL",(P21*0.19),0) -> 0 | R21: =P21*1.19 -> -78.785288 | S21: =INDEX(FX!$D$3:$O$19,MATCH(B21,FX!$B$3:$B$32,0),MATCH(D21,FX!$D$2:$O$2,0)) -> 924 | T21: Monthly Commission | U21: Provision (Based on External Report) | V21: Credit Note | W21: =VLOOKUP(I21,Map!$F$18:$H$51,3,0) -> Variable | X21: AP Completed | Y21: =VLOOKUP(L21,Map!$C$18:$D$29,2,0) -> DVT | Z21: -61174.459 | AA21: =IF(Y21="TOTAL",(Z21*0.19),0) -> 0 | AB21: =Z21*1.19 -> -72797.606 | AC21: =Z21/S21 -> -66.206124 | AD21: =IF(Y21="TOTAL",(AC21*0.19),0) -> 0 | AE21: =AC21*1.19 -> -78.785288
